Workbook

Sheet Dataset
A1: Pays | B1: IDH 2017 | C1: PIB/tête (2017) | D1: Esp Vie Naiss 2017 | E1: Années éducation (2017) | F1: Population totale (2017) | G1: Ratio Palma | H1: iso3 | I1: country
A2: Albanie | B2: 0.785 | C2: 11886 | D2: 78.5 | E2: 14.8 | F2: 2.9 | G2: 1 | H2: ALB | I2: Albania
A3: Algérie | B3: 0.754 | C3: 13802 | D3: 76.3 | E3: 14.4 | F3: 41.3 | G3: 1 | H3: DZA | I3: Algeria
A4: Allemagne | B4: 0.936 | C4: 46136 | D4: 81.2 | E4: 17 | F4: 82.1 | G4: 1.2 | H4: DEU | I4: Germany
A5: Belgique | B5: 0.916 | C5: 42156 | D5: 81.3 | E5: 19.8 | F5: 11.4 | G5: 1 | H5: BEL | I5: Belgium
A6: Cameroun | B6: 0.556 | C6: 3315 | D6: 58.6 | E6: 12.2 | F6: 24.1 | G6: 2.7 | H6: CMR | I6: Cameroon
A7: Congo | B7: 0.606 | C7: 5694 | D7: 65.1 | E7: 11.4 | F7: 5.3 | G7: 3.1 | H7: COG | I7: Congo
A8: Congo (République démocratique du) | B8: 0.457 | C8: 796 | D8: 60 | E8: 9.8 | F8: 81.3 | G8: 2.1 | H8: COD | I8: Congo (Democratic Republic of the)
A9: Côte d'Ivoire | B9: 0.492 | C9: 3481 | D9: 54.1 | E9: 9 | F9: 24.3 | G9: 2 | H9: CIV | I9: Côte d'Ivoire
A10: Croatie | B10: 0.831 | C10: 22162 | D10: 77.8 | E10: 15 | F10: 4.2 | G10: 1.1 | H10: HRV | I10: Croatia
A11: Danemark | B11: 0.929 | C11: 47918 | D11: 80.9 | E11: 19.1 | F11: 5.7 | G11: 1 | H11: DNK | I11: Denmark
A12: Espagne | B12: 0.891 | C12: 34258 | D12: 83.3 | E12: 17.9 | F12: 46.4 | G12: 1.5 | H12: ESP | I12: Spain
A13: Éthiopie | B13: 0.463 | C13: 1719 | D13: 65.9 | E13: 8.5 | F13: 105 | G13: 1.8 | H13: ETH | I13: Ethiopia
... A18: Guinée | B18: 0.459 | C18: 2067 | D18: 60.6 | E18: 9.1 | F18: 12.7 | G18: 1.3 | H18: GIN | I18: Guinea
A19: Guinée équatoriale | B19: 0.591 | C19: 19513 | D19: 57.9 | E19: 9.3 | F19: 1.3 | H19: GNQ | I19: Equatorial Guinea
A20: Hongrie | B20: 0.838 | C20: 25393 | D20: 76.1 | E20: 15.1 | F20: 9.7 | G20: 1.1 | H20: HUN | I20: Hungary
A21: Israël | B21: 0.903 | C21: 32711 | D21: 82.7 | E21: 15.9 | F21: 8.3 | G21: 2 | H21: ISR | I21: Israel
A22: Italie | B22: 0.88 | C22: 35299 | D22: 83.2 | E22: 16.3 | F22: 59.4 | G22: 1.4 | H22: ITA | I22: Italy
A23: Jordanie | B23: 0.735 | C23: 8288 | D23: 74.5 | E23: 13.1 | F23: 9.7 | G23: 1.4 | H23: JOR | I23: Jordan
A24: Liban | B24: 0.757 | C24: 13378 | D24: 79.8 | E24: 12.5 | F24: 6.1 | G24: 1.2 | H24: LBN | I24: Lebanon
A25: Libye | B25: 0.706 | C25: 11100 | D25: 72.1 | E25: 13.4 | F25: 6.4 | H25: LBY | I25: Libya
A26: Madagascar | B26: 0.519 | C26: 1358 | D26: 66.3 | E26: 10.6 | F26: 25.6 | G26: 2.1 | H26: MDG | I26: Madagascar
A27: Mali | B27: 0.427 | C27: 1953 | D27: 58.5 | E27: 7.7 | F27: 18.5 | G27: 1.3 | H27: MLI | I27: Mali
A28: Maroc | B28: 0.667 | C28: 7340 | D28: 76.1 | E28: 12.4 | F28: 35.7 | G28: 2 | H28: MAR | I28: Morocco
A29: Mauritanie | B29: 0.52 | C29: 3592 | D29: 63.4 | E29: 8.6 | F29: 4.4 | G29: 1.3 | H29: MRT | I29: Mauritania
A30: Niger | B30: 0.354 | C30: 906 | D30: 60.4 | E30: 5.4 | F30: 21.5 | G30: 1.4 | H30: NER | I30: Niger
A31: Norvège | B31: 0.953 | C31: 68012 | D31: 82.3 | E31: 17.9 | F31: 5.3 | G31: 1 | H31: NOR | I31: Norway
A32: Pays-Bas | B32: 0.931 | C32: 47900 | D32: 82 | E32: 18 | F32: 17 | G32: 1.1 | H32: NLD | I32: Netherlands
A33: Portugal | B33: 0.847 | C33: 27315 | D33: 81.4 | E33: 16.3 | F33: 10.3 | G33: 1.5 | H33: PRT | I33: Portugal
A34: République arabe syrienne | B34: 0.536 | C34: 2337 | D34: 71 | E34: 8.8 | F34: 18.3 | H34: SYR | I34: Syrian Arab Republic
A35: Royaume-Uni | B35: 0.922 | C35: 39116 | D35: 81.7 | E35: 17.4 | F35: 66.2 | G35: 1.3 | H35: GBR | I35: United Kingdom
A36: Sénégal | B36: 0.505 | C36: 2384 | D36: 67.5 | E36: 9.7 | F36: 15.9 | G36: 1.9 | H36: SEN | I36: Senegal
A37: Serbie | B37: 0.787 | C37: 13019 | D37: 75.3 | E37: 14.6 | F37: 8.8 | G37: 1 | H37: SRB | I37: Serbia
A38: Slovaquie | B38: 0.855 | C38: 29467 | D38: 77 | E38: 15 | F38: 5.4 | G38: 0.9 | H38: SVK | I38: Slovakia
A39: Slovénie | B39: 0.896 | C39: 30594 | D39: 81.1 | E39: 17.2 | F39: 2.1 | G39: 0.9 | H39: SVN | I39: Slovenia
A40: Suède | B40: 0.933 | C40: 47766 | D40: 82.6 | E40: 17.6 | F40: 9.9 | G40: 1 | H40: SWE | I40: Sweden
A41: Suisse | B41: 0.944 | C41: 57625 | D41: 83.5 | E41: 16.2 | F41: 8.5 | G41: 1.3 | H41: CHE | I41: Switzerland
A42: Tchad | B42: 0.404 | C42: 1750 | D42: 53.2 | E42: 8 | F42: 14.9 | G42: 2.2 | H42: TCD | I42: Chad
A43: Territoires palestiniens occupés | B43: 0.686 | C43: 5055 | D43: 73.6 | E43: 12.8 | F43: 4.9 | G43: 1.4 | H43: PSE | I43: Palestine, State of
A44: Tunisie | B44: 0.735 | C44: 10275 | D44: 75.9 | E44: 15.1 | F44: 11.5 | G44: 1.5 | H44: TUN | I44: Tunisia
...

Sheet Q1

Sheet Q2
A1: Pays | B1: IDH 2017 | C1: PIB/tête (2017) | D1: Esp Vie Naiss 2017 | E1: Années éducation (2017) | F1: Population totale (2017) | G1: Ratio Palma
A2: Moyenne = | B2: =AVERAGE(Dataset!B2:B45) -> 0.72931818 | C2: =AVERAGE(Dataset!C2:C45) -> 21022.159 | D2: =AVERAGE(Dataset!D2:D45) -> 73.427273 | E2: =AVERAGE(Dataset!E2:E45) -> 13.686364 | F2: =AVERAGE(Dataset!F2:F45) -> 23.106818 | G2: =AVERAGE(Dataset!G2:G45) -> 1.4878049
A3: Variance = | B3: =_xlfn.VAR.S(Dataset!B2:B45) -> 0.033685385 | C3: =_xlfn.VAR.S(Dataset!C2:C45) -> 3.3104233e+08 | D3: =_xlfn.VAR.S(Dataset!D2:D45) -> 85.765285 | E3: =_xlfn.VAR.S(Dataset!E2:E45) -> 13.370042 | F3: =_xlfn.VAR.S(Dataset!F2:F45) -> 694.40158 | G3: =_xlfn.VAR.S(Dataset!G2:G45) -> 0.26459756
A4: Ecart type = | B4: =_xlfn.STDEV.S(Dataset!B2:B45) -> 0.18353579 | C4: =_xlfn.STDEV.S(Dataset!C2:C45) -> 18194.569 | D4: =_xlfn.STDEV.S(Dataset!D2:D45) -> 9.2609549 | E4: =_xlfn.STDEV.S(Dataset!E2:E45) -> 3.6565068 | F4: =_xlfn.STDEV.S(Dataset!F2:F45) -> 26.351501 | G4: =_xlfn.STDEV.S(Dataset!G2:G45) -> 0.51439048

Sheet Q3
A1: Pays | B1: IDH 2017 | C1: PIB/tête (2017) | D1: Esp Vie Naiss 2017 | E1: Années éducation (2017) | F1: Population totale (2017) | G1: Ratio Palma
A2: Médiane = | B2: =MEDIAN(Dataset!B2:B45) -> 0.771 | C2: =MEDIAN(Dataset!C2:C45) -> 15116.5 | D2: =MEDIAN(Dataset!D2:D45) -> 76.1 | E2: =MEDIAN(Dataset!E2:E45) -> 14.7 | F2: =MEDIAN(Dataset!F2:F45) -> 11.3 | G2: =MEDIAN(Dataset!G2:G45) -> 1.3
A3: Déciles & quartiles :
A4: D1 = | B4: =PERCENTILE(Dataset!B2:B45,0.1) -> 0.4602 | C4: =PERCENTILE(Dataset!C2:C45,0.1) -> 1810.9 | D4: =PERCENTILE(Dataset!D2:D45,0.1) -> 59.02 | E4: =PERCENTILE(Dataset!E2:E45,0.1) -> 8.66 | F4: =PERCENTILE(Dataset!F2:F45,0.1) -> 4.26 | G4: =PERCENTILE(Dataset!G2:G45,0.1) -> 1
A5: Q1 = | B5: =_xlfn.QUARTILE.EXC(Dataset!B$2:B$45,1) -> 0.541 | C5: =_xlfn.QUARTILE.EXC(Dataset!C$2:C$45,1) -> 3508.75 | D5: =_xlfn.QUARTILE.EXC(Dataset!D$2:D$45,1) -> 66 | E5: =_xlfn.QUARTILE.EXC(Dataset!E$2:E$45,1) -> 10 | F5: =_xlfn.QUARTILE.EXC(Dataset!F$2:F$45,1) -> 5.55 | G5: =_xlfn.QUARTILE.EXC(Dataset!G$2:G$45,1) -> 1.05
A6: Q2 = | B6: =_xlfn.QUARTILE.EXC(Dataset!B$2:B$45,2) -> 0.771 | C6: =_xlfn.QUARTILE.EXC(Dataset!C$2:C$45,2) -> 15116.5 | D6: =_xlfn.QUARTILE.EXC(Dataset!D$2:D$45,2) -> 76.1 | E6: =_xlfn.QUARTILE.EXC(Dataset!E$2:E$45,2) -> 14.7 | F6: =_xlfn.QUARTILE.EXC(Dataset!F$2:F$45,2) -> 11.3 | G6: =_xlfn.QUARTILE.EXC(Dataset!G$2:G$45,2) -> 1.3
A7: Q3 = | B7: =_xlfn.QUARTILE.EXC(Dataset!B$2:B$45,3) -> 0.89975 | C7: =_xlfn.QUARTILE.EXC(Dataset!C$2:C$45,3) -> 35038.75 | D7: =_xlfn.QUARTILE.EXC(Dataset!D$2:D$45,3) -> 81.4 | E7: =_xlfn.QUARTILE.EXC(Dataset!E$2:E$45,3) -> 16.85 | F7: =_xlfn.QUARTILE.EXC(Dataset!F$2:F$45,3) -> 25.275 | G7: =_xlfn.QUARTILE.EXC(Dataset!G$2:G$45,3) -> 1.95
A8: D9 = | B8: =PERCENTILE(Dataset!B1:B45,0.9) -> 0.9304 | C8: =PERCENTILE(Dataset!C6:C49,0.1) -> 1746.9 | D8: =PERCENTILE(Dataset!D1:D45,0.9) -> 82.67 | E8: =PERCENTILE(Dataset!E6:E49,0.1) -> 8.59 | F8: =PERCENTILE(Dataset!F1:F45,0.9) -> 65.84 | G8: =PERCENTILE(Dataset!G6:G49,0.1) -> 1

Sheet Q4
A1: Pays | B1: Esp Vie Naiss 2017
A2: Albanie | B2: 78.5
A3: Algérie | B3: 76.3
A4: Allemagne | B4: 81.2
A5: Belgique | B5: 81.3
A6: Cameroun | B6: 58.6
A7: Congo | B7: 65.1
A8: Congo (République démocratique du) | B8: 60
A9: Côte d'Ivoire | B9: 54.1
A10: Croatie | B10: 77.8
A11: Danemark | B11: 80.9
A12: Espagne | B12: 83.3
A13: Éthiopie | B13: 65.9
... A45: Turquie | B45: 76

Sheet Q5
A1: Pays | B1: Esp Vie Naiss 2017
A2: Tchad | B2: 53.2
A3: Côte d'Ivoire | B3: 54.1
A4: Guinée équatoriale | B4: 57.9
A5: Mali | B5: 58.5
A6: Cameroun | B6: 58.6
A7: D1 | B7: 59.02
A8: Congo (République démocratique du) | B8: 60
A9: Niger | B9: 60.4
A10: Guinée | B10: 60.6
A11: Mauritanie | B11: 63.4
A12: Congo | B12: 65.1
A13: Éthiopie | B13: 65.9
... A50: Suisse | B50: 83.5

Sheet Q6
A1: Pays | B1: Esp Vie Naiss 2017
A2: Tchad | B2: 53.2
A3: Côte d'Ivoire | B3: 54.1
A4: Guinée équatoriale | B4: 57.9
A5: Mali | B5: 58.5
A6: Cameroun | B6: 58.6
A7: Congo (République démocratique du) | B7: 60
A8: Niger | B8: 60.4
A9: Guinée | B9: 60.6
A10: Mauritanie | B10: 63.4
A11: Congo | B11: 65.1
A12: Éthiopie | B12: 65.9
A13: Madagascar | B13: 66.3
... A45: Suisse | B45: 83.5

Sheet Q7
B1: IDH - PIB | C1: IDH - Esp | D1: IDH - éducation | E1: IDH - Pop | F1: IDH - Palma
A2: Covariance | B2: =COVAR(Dataset!$B2:$B45,Dataset!C2:C45) -> 2861.2549 | C2: =COVAR(Dataset!$B2:$B45,Dataset!D2:D45) -> 1.5441345 | D2: =COVAR(Dataset!$B2:$B45,Dataset!E2:E45) -> 0.63419752 | E2: =COVAR(Dataset!$B2:$B45,Dataset!F2:F45) -> -0.34254081 | F2: =COVAR(Dataset!$B2:$B45,Dataset!G2:G45) -> -0.049883224
A3: Corrélation | B3: =CORREL(Dataset!$B2:$B45,Dataset!C2:C45) -> 0.87675501 | C3: =CORREL(Dataset!$B2:$B45,Dataset!D2:D45) -> 0.92959295 | D3: =CORREL(Dataset!$B2:$B45,Dataset!E2:E45) -> 0.96698918 | E3: =CORREL(Dataset!$B2:$B45,Dataset!F2:F45) -> -0.07247203 | F3: =CORREL(Dataset!$B2:$B45,Dataset!G2:G45) -> -0.53353858

Sheet Q8
A1: Pays | B1: PIB/tête (2017) | C1: Esp Vie Naiss 2017
A2: Tchad | B2: 1750 | C2: 53.2
A3: Côte d'Ivoire | B3: 3481 | C3: 54.1
A4: Guinée équatoriale | B4: 19513 | C4: 57.9
A5: Mali | B5: 1953 | C5: 58.5
A6: Cameroun | B6: 3315 | C6: 58.6
A7: Congo (République démocratique du) | B7: 796 | C7: 60
A8: Niger | B8: 906 | C8: 60.4
A9: Guinée | B9: 2067 | C9: 60.6
A10: Mauritanie | B10: 3592 | C10: 63.4
A11: Congo | B11: 5694 | C11: 65.1
A12: Éthiopie | B12: 1719 | C12: 65.9
A13: Madagascar | B13: 1358 | C13: 66.3
... A45: Suisse | B45: 57625 | C45: 83.5
A46: Coefficient de corrélation | B46: =CORREL(B2:B45,C2:C45) -> 0.76547392
A47: Coefficient de détermination | B47: =RSQ(B2:B45,C2:C45) -> 0.58595033

Sheet Q9
A1: Pays | B1: Esp Vie Naiss 2017 | C1: PIB/tête (2017) | D1: Années éducation (2017) | E1: Population totale (2017)
A2: Albanie | B2: 78.5 | C2: 11886 | D2: 14.8 | E2: 2.9
A3: Algérie | B3: 76.3 | C3: 13802 | D3: 14.4 | E3: 41.3 | J3: RAPPORT DÉTAILLÉ
A4: Allemagne | B4: 81.2 | C4: 46136 | D4: 17 | E4: 82.1
A5: Belgique | B5: 81.3 | C5: 42156 | D5: 19.8 | E5: 11.4 | J5: Statistiques de la régression
A6: Cameroun | B6: 58.6 | C6: 3315 | D6: 12.2 | E6: 24.1 | J6: Coefficient de détermination multiple | K6: 0.8927021
A7: Congo | B7: 65.1 | C7: 5694 | D7: 11.4 | E7: 5.3 | J7: Coefficient de détermination R^2 | K7: 0.79691704
A8: Congo (République démocratique du) | B8: 60 | C8: 796 | D8: 9.8 | E8: 81.3 | J8: Coefficient de détermination R^2 | K8: 0.78168581
A9: Côte d'Ivoire | B9: 54.1 | C9: 3481 | D9: 9 | E9: 24.3 | J9: Erreur-type | K9: 4.3270982
A10: Croatie | B10: 77.8 | C10: 22162 | D10: 15 | E10: 4.2 | J10: Observations | K10: 44
A11: Danemark | B11: 80.9 | C11: 47918 | D11: 19.1 | E11: 5.7
A12: Espagne | B12: 83.3 | C12: 34258 | D12: 17.9 | E12: 46.4 | J12: ANALYSE DE VARIANCE
A13: Éthiopie | B13: 65.9 | C13: 1719 | D13: 8.5 | E13: 105 | K13: Degré de liberté | L13: Somme des carrés | M13: Moyenne des carrés | N13: F | O13: Valeur critique de F
A14: Finlande | B14: 81.5 | C14: 41002 | D14: 17.6 | E14: 5.5 | J14: Régression | K14: 3 | L14: 2938.9561 | M14: 979.65205 | N14: 52.32128 | O14: 6.5730729e-14
A15: France | B15: 82.7 | C15: 39254 | D15: 16.4 | E15: 65 | J15: Résidus | K15: 40 | L15: 748.95114 | M15: 18.723778
A16: Gabon | B16: 66.5 | C16: 16431 | D16: 12.8 | E16: 2 | J16: Total | K16: 43 | L16: 3687.9073
A17: Grèce | B17: 81.4 | C17: 24648 | D17: 17.3 | E17: 11.2
A18: Guinée | B18: 60.6 | C18: 2067 | D18: 9.1 | E18: 12.7 | K18: Coefficients | L18: Erreur-type | M18: Statistique t | N18: Probabilité | O18: Limite inférieure pour seuil de confiance = 95% | P18: Limite supérieure pour seuil de confiance = 95% | Q18: Limite inférieure pour seuil de confiance = 95,0% | R18: Limite supérieure pour seuil de confiance = 95,0%
A19: Guinée équatoriale | B19: 57.9 | C19: 19513 | D19: 9.3 | E19: 1.3 | J19: Constante | K19: 43.04944 | L19: 3.6206133 | M19: 11.890096 | N19: 1.044958e-14 | O19: 35.731908 | P19: 50.366973 | Q19: 35.731908 | R19: 50.366973
A20: Hongrie | B20: 76.1 | C20: 25393 | D20: 15.1 | E20: 9.7 | J20: PIB/tête (2017) | K20: 2.4326801e-05 | L20: 6.7299326e-05 | M20: 0.36147168 | N20: 0.71964929 | O20: -0.00011169021 | P20: 0.00016034381 | Q20: -0.00011169021 | R20: 0.00016034381
A21: Israël | B21: 82.7 | C21: 32711 | D21: 15.9 | E21: 8.3 | J21: Années éducation (2017) | K21: 2.1596363 | L21: 0.3351164 | M21: 6.4444364 | N21: 1.1219509e-07 | O21: 1.4823408 | P21: 2.8369318 | Q21: 1.4823408 | R21: 2.8369318
A22: Italie | B22: 83.2 | C22: 35299 | D22: 16.3 | E22: 59.4 | J22: Population totale (2017) | K22: 0.013366749 | L22: 0.025086725 | M22: 0.53282161 | N22: 0.597105 | O22: -0.037335413 | P22: 0.064068911 | Q22: -0.037335413 | R22: 0.064068911
A23: Jordanie | B23: 74.5 | C23: 8288 | D23: 13.1 | E23: 9.7
A24: Liban | B24: 79.8 | C24: 13378 | D24: 12.5 | E24: 6.1
A25: Libye | B25: 72.1 | C25: 11100 | D25: 13.4 | E25: 6.4
A26: Madagascar | B26: 66.3 | C26: 1358 | D26: 10.6 | E26: 25.6
A27: Mali | B27: 58.5 | C27: 1953 | D27: 7.7 | E27: 18.5
A28: Maroc | B28: 76.1 | C28: 7340 | D28: 12.4 | E28: 35.7
A29: Mauritanie | B29: 63.4 | C29: 3592 | D29: 8.6 | E29: 4.4
A30: Niger | B30: 60.4 | C30: 906 | D30: 5.4 | E30: 21.5
A31: Norvège | B31: 82.3 | C31: 68012 | D31: 17.9 | E31: 5.3
A32: Pays-Bas | B32: 82 | C32: 47900 | D32: 18 | E32: 17
A33: Portugal | B33: 81.4 | C33: 27315 | D33: 16.3 | E33: 10.3
A34: République arabe syrienne | B34: 71 | C34: 2337 | D34: 8.8 | E34: 18.3
... A45: Turquie | B45: 76 | C45: 24804 | D45: 15.2 | E45: 80.7

Sheet Q10
A1: Pays | B1: Esp Vie Naiss 2017 | C1: Population totale (2017) | D1: Ecart carré pondéré
A2: Albanie | B2: 78.5 | C2: 2.9 | D2: =C2*(B2-J$7)^2 -> 73.152371
A3: Algérie | B3: 76.3 | C3: 41.3 | D3: =C3*(B3-J$7)^2 -> 329.00392
A4: Allemagne | B4: 81.2 | C4: 82.1 | D4: =C4*(B4-J$7)^2 -> 4896.1287
A5: Belgique | B5: 81.3 | C5: 11.4 | D5: =C5*(B5-J$7)^2 -> 697.57339
A6: Cameroun | B6: 58.6 | C6: 24.1 | D6: =C6*(B6-J$7)^2 -> 5334.3335 | I6: Espérance de vie non pondérée | J6: =AVERAGE(B2:B45) -> 73.427273
A7: Congo | B7: 65.1 | C7: 5.3 | D7: =C7*(B7-J$7)^2 -> 371.97215 | I7: Espérance de vie pondérée | J7: =SUMPRODUCT(B2:B45,C2:C45)/SUM(C2:C45) -> 73.477555
A8: Congo (République démocratique du) | B8: 60 | C8: 81.3 | D8: =C8*(B8-J$7)^2 -> 14767.697 | I8: Variance inter-Pays | J8: =SUM(D2:D45)/SUM(C2:C45) -> 86.694293
A9: Côte d'Ivoire | B9: 54.1 | C9: 24.3 | D9: =C9*(B9-J$7)^2 -> 9124.398
A10: Croatie | B10: 77.8 | C10: 4.2 | D10: =C10*(B10-J$7)^2 -> 78.470835
A11: Danemark | B11: 80.9 | C11: 5.7 | D11: =C11*(B11-J$7)^2 -> 314.02835
A12: Espagne | B12: 83.3 | C12: 46.4 | D12: =C12*(B12-J$7)^2 -> 4476.6919
A13: Éthiopie | B13: 65.9 | C13: 105 | D13: =C13*(B13-J$7)^2 -> 6029.0304
A14: Finlande | B14: 81.5 | C14: 5.5 | D14: =C14*(B14-J$7)^2 -> 353.97795
A15: France | B15: 82.7 | C15: 65 | D15: =C15*(B15-J$7)^2 -> 5528.4772
A16: Gabon | B16: 66.5 | C16: 2 | D16: =C16*(B16-J$7)^2 -> 97.372543
A17: Grèce | B17: 81.4 | C17: 11.2 | D17: =C17*(B17-J$7)^2 -> 702.96954
A18: Guinée | B18: 60.6 | C18: 12.7 | D18: =C18*(B18-J$7)^2 -> 2106.059
A19: Guinée équatoriale | B19: 57.9 | C19: 1.3 | D19: =C19*(B19-J$7)^2 -> 315.45828
A20: Hongrie | B20: 76.1 | C20: 9.7 | D20: =C20*(B20-J$7)^2 -> 66.709021
... A45: Turquie | B45: 76 | C45: 80.7 | D45: =C45*(B45-J$7)^2 -> 513.47228
